/disk2/yuchen/yuchen/coiltraine/logger/monitorer.py:120: UserWarning: loadtxt: Empty input file: "<_io.BufferedReader name='_logs/sample/coil_icra/drive_TestT1_Town01_csv/control_output_.csv'>"
  delimiter=",", skiprows=1)
ERROR:root:(127.0.0.1:49458) connection closed
ERROR:root:(127.0.0.1:49458) connection closed
ERROR:root:(127.0.0.1:49458) connection closed
ERROR:root:(127.0.0.1:49458) connection closed
ERROR:root:(127.0.0.1:49458) failed to read data: timed out
ERROR:root:(127.0.0.1:49458) connection closed
ERROR:root:(127.0.0.1:49458) connection closed
ERROR:root:(127.0.0.1:49458) connection closed
ERROR:root:(127.0.0.1:49458) connection closed
ERROR:root:(127.0.0.1:49458) connection closed
ERROR:root:(127.0.0.1:49458) connection closed
ERROR:root:(127.0.0.1:49458) connection closed
ERROR:root:(127.0.0.1:49458) connection closed
ERROR:root:(127.0.0.1:49458) connection closed
ERROR:root:(127.0.0.1:49458) connection closed
ERROR:root:(127.0.0.1:49458) connection closed
INFO:coil_icra_drive_TestT1_Town01:{'Iterating': {'Checkpoint': 2000, 'Agent': "tensor(0.2829, device='cuda:0', grad_fn=<SelectBackward>)"}}
/disk2/yuchen/yuchen/coiltraine/carla08/driving_benchmark/metrics.py:340: RuntimeWarning: invalid value encountered in true_divide
  experiment_results_matrix[:, header.index('number_red_lights')]))).tolist()
Traceback (most recent call last):
  File "/disk2/yuchen/yuchen/coiltraine/coil_core/run_drive.py", line 128, in driving_benchmark
    checkpoint_number, town_name, g_conf.PROCESS_NAME.split('_')[1])
  File "/disk2/yuchen/yuchen/coiltraine/plotter/plot_on_map.py", line 170, in plot_episodes_tracks
    episodes_positions, travelled_distances = split_episodes(meas_file)
  File "/disk2/yuchen/yuchen/coiltraine/plotter/plot_on_map.py", line 77, in split_episodes
    previous_pos = [details_matrix[0, header_details.index('pos_x')],
ValueError: 'pos_x' is not in list
INFO:coil_icra_drive_TestT1_Town01:{'Error': {'Message': 'Something Happened'}}
Traceback (most recent call last):
  File "/disk2/yuchen/yuchen/coiltraine/coil_core/run_drive.py", line 128, in driving_benchmark
    checkpoint_number, town_name, g_conf.PROCESS_NAME.split('_')[1])
  File "/disk2/yuchen/yuchen/coiltraine/plotter/plot_on_map.py", line 170, in plot_episodes_tracks
    episodes_positions, travelled_distances = split_episodes(meas_file)
  File "/disk2/yuchen/yuchen/coiltraine/plotter/plot_on_map.py", line 77, in split_episodes
    previous_pos = [details_matrix[0, header_details.index('pos_x')],
ValueError: 'pos_x' is not in list

During handling of the above exception, another exception occurred:

Traceback (most recent call last):
  File "/disk2/yuchen/yuchen/coiltraine/coil_core/run_drive.py", line 257, in execute
    exp_alias, params, control_filename, task_list)
  File "/disk2/yuchen/yuchen/coiltraine/coil_core/run_drive.py", line 153, in driving_benchmark
    exit(1)
  File "/home/nonews/miniconda2/envs/coiltraine/lib/python3.5/_sitebuiltins.py", line 26, in __call__
    raise SystemExit(code)
SystemExit: 1
INFO:coil_icra_drive_TestT1_Town01:{'Error': {'Message': 'Something happened'}}
