/disk1/yuchen/coiltraine/logger/monitorer.py:120: UserWarning: loadtxt: Empty input file: "<_io.BufferedReader name='_logs/sample/coil_icra/drive_TestT1_Town01_csv/control_output_.csv'>"
  delimiter=",", skiprows=1)
ERROR:root:(127.0.0.1:52073) failed to connect: [Errno 111] Connection refused
INFO:coil_icra_drive_TestT1_Town01:{'Error': {'Message': 'Killed By User'}}
Traceback (most recent call last):
  File "/disk1/yuchen/coiltraine/carla08/driving_benchmark/driving_benchmark.py", line 495, in run_driving_benchmark
    with make_carla_client(host, port) as client:
  File "/home/yuliang/miniconda2/envs/coiltraine/lib/python3.5/contextlib.py", line 59, in __enter__
    return next(self.gen)
  File "/disk1/yuchen/coiltraine/carla08/client.py", line 35, in make_carla_client
    with util.make_connection(CarlaClient, host, world_port, timeout) as client:
  File "/home/yuliang/miniconda2/envs/coiltraine/lib/python3.5/contextlib.py", line 59, in __enter__
    return next(self.gen)
  File "/disk1/yuchen/coiltraine/carla08/util.py", line 19, in make_connection
    client.connect()
  File "/disk1/yuchen/coiltraine/carla08/client.py", line 54, in connect
    self._world_client.connect(connection_attempts)
  File "/disk1/yuchen/coiltraine/carla08/tcp.py", line 48, in connect
    self._reraise_exception_as_tcp_error('failed to connect', error)
  File "/disk1/yuchen/coiltraine/carla08/tcp.py", line 97, in _reraise_exception_as_tcp_error
    raise TCPConnectionError('%s%s: %s' % (self._logprefix, message, exception))
carla08.tcp.TCPConnectionError: (127.0.0.1:52073) failed to connect: [Errno 111] Connection refused

During handling of the above exception, another exception occurred:

Traceback (most recent call last):
  File "/disk1/yuchen/coiltraine/coil_core/run_drive.py", line 102, in driving_benchmark
    , True, params['host'], port)
  File "/disk1/yuchen/coiltraine/carla08/driving_benchmark/driving_benchmark.py", line 535, in run_driving_benchmark
    time.sleep(1)
KeyboardInterrupt

During handling of the above exception, another exception occurred:

Traceback (most recent call last):
  File "/disk1/yuchen/coiltraine/coil_core/run_drive.py", line 257, in execute
    exp_alias, params, control_filename, task_list)
  File "/disk1/yuchen/coiltraine/coil_core/run_drive.py", line 147, in driving_benchmark
    exit(1)
  File "/home/yuliang/miniconda2/envs/coiltraine/lib/python3.5/_sitebuiltins.py", line 26, in __call__
    raise SystemExit(code)
SystemExit: 1
INFO:coil_icra_drive_TestT1_Town01:{'Error': {'Message': 'Something happened'}}
